Workbook

Sheet 00_HuongDan
B3: BUỔI 10 · DỰ ÁN CUỐI KHÓA — CHU KỲ DỰ BÁO THÁNG
B4: ERX · Demand Planning & Forecasting in Practice · BẢN HỌC VIÊN · Thư Nguyễn · thu.minh090997@gmail.com
B6: Mục tiêu
B7: • | C7: Chạy trọn một chu kỳ dự báo hằng tháng cho 6 chuỗi SKU × kênh của portfolio được giao.
B8: • | C8: Chọn mô hình bằng sai số ngoài mẫu, đắp thông tin kinh doanh có ghi giả định, tính tồn kho an toàn.
B9: • | C9: Bàn giao kế hoạch nhu cầu CHƯA giới hạn năng lực cho module Production Planning và tóm tắt S&OP 1 trang.
B11: Nhiệm vụ
B12: Sheet | C12: Việc cần làm | D12: Thời lượng
B13: 01_Portfolio | C13: Chọn 6 chuỗi ở ô vàng (danh sách thả xuống) → 36 tháng nhu cầu tự hiện ra. | D13: Tuần 7
B14: 02_NhatKy_LamSach | C14: Ghi mọi điều chỉnh dữ liệu (bạn có thể dùng dữ liệu gốc sales_history thay vì bản sạch — được cộng điểm). | D14: Tuần 7–8
B15: 03_ChonMoHinh | C15: Ít nhất 3 phương pháp/chuỗi (gồm 1 mốc Naive/Seasonal Naive); WMAPE, Bias, MASE trên 6 tháng test; phương pháp chọn + lý do. | D15: Tuần 8
B16: 04_DuBao_12T | C16: Dự báo thống kê 10/2026–09/2027, điều chỉnh (KM, Tết, sự kiện) có mã giả định, số đồng thuận. | D16: Tuần 8–9
B17: 05_GiaDinh | C17: Nhật ký giả định: mỗi điều chỉnh một dòng, có nguồn/bằng chứng. | D17: Tuần 9
B18: 06_TonKho | C18: σ sai số ngoài mẫu, lead time, mức phục vụ, Safety Stock, ROP. | D18: Tuần 9
B19: 07_BanGiao_PP | C19: File bàn giao cho Production Planning (tự động lấy từ sheet 04 và 06) + ghi chú rủi ro. | D19: Tuần 10
B20: 08_SOP_1Trang | C20: Tóm tắt S&OP: sản lượng → giá trị, 3 rủi ro/cơ hội, quyết định cần lãnh đạo chốt. | D20: Tuần 10
B21: 09_TuKiemTra | C21: Tự chấm theo rubric trước khi nộp. | D21: Trước hạn
B23: Dữ liệu
C24: demand_clean (36 tháng, đã làm sạch, cột demand_ex_event), promo_calendar, calendar, sku_master.
B26: Quy ước màu
B27: Ví dụ 123 | C27: Ô nhiệm vụ: học viên điền công thức (rê chuột xem gợi ý trong comment)
B28: Ví dụ 123 | C28: Chữ xanh dương trên nền vàng: tham số/giả định có thể thay đổi
B29: Ví dụ 123 | C29: Nền xanh nhạt: công thức đáp án (chỉ có ở bản đáp án)
B30: Ví dụ 123 | C30: Chữ xanh lá: liên kết từ sheet khác
B32: Ghi chú
B33: • | C33: Portfolio P1–P6 do giảng viên giao (xem Capstone_Brief). Phương án B: dữ liệu công ty đã ẩn danh — phải được duyệt ở Bài tập 7.
B34: • | C34: Có thể làm bằng Excel, Forecasting Lab hoặc Python — nhưng con số cuối phải nằm trong file này.
B35: • | C35: Nộp: file này + báo cáo 6–8 trang + slide 8 phút, trước Buổi 10 ít nhất 48 giờ.
B37: Quy ước toàn khóa: e = Actual − Forecast (e > 0: dự báo thấp). Tiền: nghìn đồng nếu không ghi khác. Dữ liệu Mekong Bloom Foods là công ty GIẢ ĐỊNH phục vụ giảng dạy.

Sheet Data
A1: Tháng | B1: N01|GT | C1: N01|MT | D1: N02|GT | E1: N02|MT | F1: N03|GT | G1: N03|MT | H1: N04|GT | I1: N04|MT | J1: N05|GT | K1: N05|MT | L1: S01|GT | M1: S01|MT | N1: S02|GT | O1: S02|MT | P1: S03|GT | Q1: S03|MT | R1: S04|GT | S1: S04|MT | T1: S05|GT | U1: S05|MT | V1: S06|GT | W1: S06|MT | X1: B01|GT | Y1: B01|MT | Z1: B02|GT | AA1: B02|MT | AB1: B03|GT | AC1: B03|MT | AD1: B04|GT | AE1: B04|MT | AF1: B05|GT | AG1: B05|MT | AH1: K01|GT | AI1: K01|MT | AJ1: K02|GT | AK1: K02|MT | AL1: K03|GT | AM1: K03|MT | AN1: K04|MT | AO1: H01|GT | AP1: H02|GT | AQ1: H03|GT
A2: 2023-10 | B2: 49518 | C2: 15021 | D2: 19251 | E2: 7632 | F2: 4104 | G2: 4801 | H2: 7631 | I2: 4175 | L2: 8455 | M2: 3940 | N2: 7375 | O2: 3789 | P2: 2823 | Q2: 2637 | R2: 5627 | S2: 3344 | T2: 2749 | U2: 1496 | V2: 4095 | W2: 1803 | X2: 9030 | Y2: 3943 | Z2: 8519 | AA2: 3842 | AB2: 3801 | AC2: 5678 | AD2: 2408 | AE2: 1605 | AF2: 806 | AG2: 2300 | AH2: 3287 | AI2: 5927 | AJ2: 633 | AK2: 694 | AL2: 1148 | AM2: 378 | AN2: 0 | AO2: 364 | AP2: 418 | AQ2: 4
A3: 2023-11 | B3: 39293 | C3: 12157 | D3: 19488 | E3: 6589 | F3: 4659 | G3: 5508 | H3: 5950 | I3: 4018 | L3: 8881 | M3: 4296 | N3: 7441 | O3: 2439 | P3: 1863 | Q3: 2059 | R3: 5136 | S3: 2515 | T3: 2804 | U3: 1701 | V3: 3656 | W3: 2384 | X3: 10818 | Y3: 4579 | Z3: 9242 | AA3: 2073 | AB3: 3441 | AC3: 4740 | AD3: 1807 | AE3: 1607 | AF3: 734 | AG3: 1987 | AH3: 3095 | AI3: 3020 | AJ3: 2140 | AK3: 2119 | AL3: 1387 | AM3: 1690 | AN3: 222 | AO3: 183 | AP3: 0 | AQ3: 4
A4: 2023-12 | B4: 36704 | C4: 13386 | D4: 15801 | E4: 7962 | F4: 4311 | G4: 5184 | H4: 6605 | I4: 3295 | L4: 9215 | M4: 3950 | N4: 7122 | O4: 3250 | P4: 2576 | Q4: 1859 | R4: 6056 | S4: 2390 | T4: 2393 | U4: 1671 | V4: 2682 | W4: 1392 | X4: 9463 | Y4: 5175 | Z4: 8109 | AA4: 3912 | AB4: 3145 | AC4: 6094 | AD4: 2010 | AE4: 1134 | AF4: 817 | AG4: 2597 | AH4: 3235 | AI4: 4719 | AJ4: 2497 | AK4: 4215 | AL4: 670 | AM4: 986 | AN4: 230 | AO4: 0 | AP4: 211 | AQ4: 0
A5: 2024-01 | B5: 46985 | C5: 14957 | D5: 18541 | E5: 9261 | F5: 5114 | G5: 6215 | H5: 7632 | I5: 3268 | L5: 12879 | M5: 6347 | N5: 8795 | O5: 3743 | P5: 2823 | Q5: 2258 | R5: 8494 | S5: 3393 | T5: 2325 | U5: 1514 | V5: 3705 | W5: 1801 | X5: 7528 | Y5: 4481 | Z5: 6030 | AA5: 2687 | AB5: 3219 | AC5: 3460 | AD5: 4105 | AE5: 2558 | AF5: 612 | AG5: 2153 | AH5: 3893 | AI5: 3517 | AJ5: 3033 | AK5: 3427 | AL5: 1318 | AM5: 917 | AN5: 1265 | AO5: 143 | AP5: 0 | AQ5: 4
A6: 2024-02 | B6: 40022 | C6: 26309 | D6: 14046 | E6: 7296 | F6: 3545 | G6: 4578 | H6: 5727 | I6: 2624 | L6: 8537 | M6: 3700 | N6: 7103 | O6: 3088 | P6: 2244 | Q6: 1632 | R6: 6178 | S6: 2708 | T6: 1766 | U6: 1553 | V6: 2294 | W6: 1123 | X6: 10148 | Y6: 5008 | Z6: 7814 | AA6: 2868 | AB6: 3319 | AC6: 3823 | AD6: 1517 | AE6: 1770 | AF6: 781 | AG6: 3468 | AH6: 2709 | AI6: 6222 | AJ6: 873 | AK6: 1090 | AL6: 878 | AM6: 1390 | AN6: 469 | AO6: 368 | AP6: 181 | AQ6: 0
A7: 2024-03 | B7: 39799 | C7: 13173 | D7: 15092 | E7: 6354 | F7: 4808 | G7: 5817 | H7: 5885 | I7: 3275 | L7: 10625 | M7: 5171 | N7: 7693 | O7: 3593 | P7: 3674 | Q7: 1820 | R7: 7064 | S7: 2748 | T7: 2252 | U7: 1864 | V7: 2878 | W7: 1562 | X7: 11681 | Y7: 6378 | Z7: 9282 | AA7: 3799 | AB7: 3680 | AC7: 5251 | AD7: 1977 | AE7: 2062 | AF7: 1144 | AG7: 1675 | AH7: 2167 | AI7: 2530 | AJ7: 46 | AK7: 63 | AL7: 26 | AM7: 928 | AN7: 0 | AO7: 0 | AP7: 0 | AQ7: 8
A8: 2024-04 | B8: 38450 | C8: 21068 | D8: 16100 | E8: 7293 | F8: 4860 | G8: 5599 | H8: 5614 | I8: 3021 | L8: 8777 | M8: 3789 | N8: 7273 | O8: 3267 | P8: 4234 | Q8: 2610 | R8: 6217 | S8: 3079 | T8: 2282 | U8: 1782 | V8: 3032 | W8: 1299 | X8: 15566 | Y8: 6614 | Z8: 11265 | AA8: 6492 | AB8: 3138 | AC8: 4618 | AD8: 2832 | AE8: 1652 | AF8: 1325 | AG8: 2734 | AH8: 2451 | AI8: 3265 | AJ8: 43 | AK8: 75 | AL8: 0 | AM8: 1330 | AN8: 0 | AO8: 285 | AP8: 655 | AQ8: 0
A9: 2024-05 | B9: 38657 | C9: 13563 | D9: 13428 | E9: 7065 | F9: 4743 | G9: 5964 | H9: 5380 | I9: 3291 | L9: 9354 | M9: 4327 | N9: 7192 | O9: 3560 | P9: 4189 | Q9: 3022 | R9: 6518 | S9: 2579 | T9: 2550 | U9: 2120 | V9: 3019 | W9: 1212 | X9: 16912 | Y9: 6544 | Z9: 13079 | AA9: 4567 | AB9: 3397 | AC9: 3503 | AD9: 2541 | AE9: 2306 | AF9: 1536 | AG9: 4491 | AH9: 3212 | AI9: 3532 | AJ9: 38 | AK9: 69 | AL9: 190 | AM9: 509 | AN9: 0 | AO9: 206 | AP9: 0 | AQ9: 0
A10: 2024-06 | B10: 39981 | C10: 14935 | D10: 18158 | E10: 7149 | F10: 5280 | G10: 12677 | H10: 5870 | I10: 3322 | L10: 9169 | M10: 4658 | N10: 7538 | O10: 3437 | P10: 4564 | Q10: 3173 | R10: 6508 | S10: 2229 | T10: 2386 | U10: 1748 | V10: 3968 | W10: 1347 | X10: 17536 | Y10: 7912 | Z10: 13321 | AA10: 7234 | AB10: 2542 | AC10: 6627 | AD10: 2746 | AE10: 1769 | AF10: 1712 | AG10: 3500 | AH10: 2832 | AI10: 3586 | AJ10: 33 | AK10: 55 | AL10: 833 | AM10: 562 | AN10: 0 | AO10: 501 | AP10: 101 | AQ10: 4
A11: 2024-07 | B11: 39408 | C11: 14972 | D11: 21518 | E11: 7865 | F11: 4629 | G11: 6512 | H11: 5579 | I11: 3213 | L11: 8985 | M11: 4942 | N11: 5982 | O11: 3776 | P11: 5809 | Q11: 4854 | R11: 6275 | S11: 2211 | T11: 2661 | U11: 1873 | V11: 3734 | W11: 1387 | X11: 16688 | Y11: 7745 | Z11: 14280 | AA11: 4903 | AB11: 3268 | AC11: 4841 | AD11: 2349 | AE11: 1931 | AF11: 1454 | AG11: 3746 | AH11: 2635 | AI11: 3542 | AJ11: 45 | AK11: 67 | AL11: 916 | AM11: 529 | AN11: 0 | AO11: 818 | AP11: 163 | AQ11: 0
A12: 2024-08 | B12: 53647 | C12: 16536 | D12: 19379 | E12: 8599 | F12: 5694 | G12: 10427 | H12: 6263 | I12: 3577 | L12: 8800 | M12: 4144 | N12: 7528 | O12: 3861 | P12: 5480 | Q12: 5062 | R12: 5995 | S12: 2668 | T12: 2431 | U12: 2415 | V12: 3765 | W12: 1277 | X12: 15900 | Y12: 9782 | Z12: 10575 | AA12: 3902 | AB12: 4320 | AC12: 7487 | AD12: 2118 | AE12: 2127 | AF12: 1773 | AG12: 4185 | AH12: 2354 | AI12: 4410 | AJ12: 48 | AK12: 73 | AL12: 968 | AM12: 115 | AN12: 0 | AO12: 614 | AP12: 0 | AQ12: 4
A13: 2024-09 | B13: 51728 | C13: 16514 | D13: 14912 | E13: 6889 | F13: 5344 | G13: 5595 | H13: 5542 | I13: 3179 | L13: 8120 | M13: 5857 | N13: 7728 | O13: 4282 | P13: 4212 | Q13: 3026 | R13: 7705 | S13: 2813 | T13: 2705 | U13: 2105 | V13: 3139 | W13: 2002 | X13: 15632 | Y13: 5382 | Z13: 9397 | AA13: 3975 | AB13: 4450 | AC13: 5100 | AD13: 2206 | AE13: 3178 | AF13: 1877 | AG13: 3554 | AH13: 4439 | AI13: 7911 | AJ13: 129 | AK13: 165 | AL13: 1591 | AM13: 933 | AN13: 0 | AO13: 647 | AP13: 0 | AQ13: 0
... A22: 2025-06 | B22: 35593 | C22: 22012 | D22: 20248 | E22: 6115 | F22: 5955 | G22: 8941 | H22: 4411 | I22: 2278 | L22: 9820 | M22: 3966 | N22: 8190 | O22: 3927 | P22: 6290 | Q22: 4193 | R22: 7040 | S22: 2682 | T22: 2122 | U22: 1390 | V22: 3014 | W22: 1378 | X22: 22664 | Y22: 9134 | Z22: 12244 | AA22: 5307 | AB22: 4391 | AC22: 4328 | AD22: 2292 | AE22: 1728 | AF22: 2710 | AG22: 5410 | AH22: 3747 | AI22: 3949 | AJ22: 36 | AK22: 63 | AL22: 1548 | AM22: 512 | AN22: 0 | AO22: 369 | AP22: 146 | AQ22: 0
A23: 2025-07 | B23: 48734 | C23: 14357 | D23: 23287 | E23: 10061 | F23: 7520 | G23: 8567 | H23: 5026 | I23: 3296 | K23: 9382 | L23: 8838 | M23: 4958 | N23: 8715 | O23: 3784 | P23: 3113 | Q23: 5187 | R23: 7131 | S23: 2219 | T23: 1925 | U23: 1148 | V23: 3176 | W23: 2241 | X23: 17202 | Y23: 7680 | Z23: 13941 | AA23: 5368 | AB23: 3887 | AC23: 3558 | AD23: 2520 | AE23: 1819 | AF23: 2166 | AG23: 3662 | AH23: 3112 | AI23: 3997 | AJ23: 30 | AK23: 68 | AL23: 1116 | AM23: 915 | AN23: 0 | AO23: 967 | AP23: 0 | AQ23: 0
A24: 2025-08 | B24: 47459 | C24: 29371 | D24: 20493 | E24: 6782 | F24: 5999 | G24: 8985 | H24: 6199 | I24: 2176 | K24: 4756 | L24: 8873 | M24: 4394 | N24: 8610 | O24: 3642 | P24: 5262 | Q24: 3090 | R24: 6000 | S24: 2416 | T24: 2809 | U24: 1536 | V24: 3381 | W24: 1247 | X24: 14835 | Y24: 7374 | Z24: 11886 | AA24: 4275 | AB24: 4687 | AC24: 7381 | AD24: 2262 | AE24: 2234 | AF24: 2395 | AG24: 2786 | AH24: 3801 | AI24: 5984 | AJ24: 50 | AK24: 66 | AL24: 1327 | AM24: 876 | AN24: 0 | AO24: 309 | AP24: 0 | AQ24: 0
A25: 2025-09 | B25: 54745 | C25: 15047 | D25: 20331 | E25: 7717 | F25: 7101 | G25: 11925 | H25: 5591 | I25: 3723 | J25: 13630 | K25: 1825 | L25: 10556 | M25: 4385 | N25: 7985 | O25: 3977 | P25: 2266 | Q25: 3015 | R25: 8153 | S25: 2964 | T25: 1935 | U25: 1819 | V25: 3694 | W25: 2149 | X25: 12569 | Y25: 6018 | Z25: 9484 | AA25: 4185 | AB25: 4423 | AC25: 5876 | AD25: 2671 | AE25: 2405 | AF25: 1552 | AG25: 2103 | AH25: 3466 | AI25: 7310 | AJ25: 59 | AK25: 114 | AL25: 1031 | AM25: 218 | AN25: 185 | AO25: 676 | AP25: 177 | AQ25: 0
A26: 2025-10 | B26: 49986 | C26: 19273 | D26: 16851 | E26: 6584 | F26: 7595 | G26: 6515 | H26: 5277 | I26: 2513 | J26: 5728 | K26: 3547 | L26: 10977 | M26: 3960 | N26: 6128 | O26: 5412 | P26: 2799 | Q26: 3139 | R26: 7421 | S26: 2114 | T26: 1742 | U26: 1817 | V26: 3996 | W26: 1423 | X26: 10881 | Y26: 6517 | Z26: 8992 | AA26: 3904 | AB26: 4025 | AC26: 5208 | AD26: 2405 | AE26: 1949 | AF26: 967 | AG26: 3857 | AH26: 3760 | AI26: 3751 | AJ26: 381 | AK26: 690 | AL26: 935 | AM26: 205 | AN26: 0 | AO26: 205 | AP26: 99 | AQ26: 0
A27: 2025-11 | B27: 46973 | C27: 25750 | D27: 20059 | E27: 13568 | F27: 6170 | G27: 7909 | H27: 5054 | I27: 2424 | J27: 2143 | K27: 1887 | L27: 9901 | M27: 4728 | N27: 8005 | O27: 3342 | P27: 3721 | Q27: 2473 | R27: 7044 | S27: 3891 | T27: 2173 | U27: 1406 | V27: 3536 | W27: 1120 | X27: 9440 | Y27: 5935 | Z27: 8678 | AA27: 4268 | AB27: 3290 | AC27: 4932 | AD27: 2432 | AE27: 2233 | AF27: 1250 | AG27: 2818 | AH27: 2923 | AI27: 5389 | AJ27: 1679 | AK27: 3256 | AL27: 713 | AM27: 1204 | AN27: 219 | AO27: 102 | AP27: 172 | AQ27: 12
A28: 2025-12 | B28: 41917 | C28: 14583 | D28: 17409 | E28: 6866 | F28: 7823 | G28: 11896 | H28: 5294 | I28: 2332 | J28: 1906 | K28: 2504 | L28: 9275 | M28: 4827 | N28: 9070 | O28: 4111 | P28: 3397 | Q28: 2741 | R28: 7979 | S28: 2826 | T28: 2412 | U28: 1796 | V28: 3312 | W28: 1572 | X28: 7311 | Y28: 5906 | Z28: 8423 | AA28: 3477 | AB28: 3919 | AC28: 4456 | AD28: 1896 | AE28: 1973 | AF28: 812 | AG28: 3740 | AH28: 3195 | AI28: 3926 | AJ28: 2382 | AK28: 4895 | AL28: 875 | AM28: 820 | AN28: 230 | AO28: 343 | AP28: 414 | AQ28: 0
A29: 2026-01 | B29: 53192 | C29: 28199 | D29: 18992 | E29: 9367 | F29: 8356 | G29: 8550 | H29: 4503 | I29: 2637 | J29: 1721 | K29: 3603 | L29: 13773 | M29: 6741 | N29: 10437 | O29: 4243 | P29: 2721 | Q29: 2705 | R29: 8969 | S29: 3680 | T29: 2769 | U29: 1546 | V29: 4600 | W29: 1689 | X29: 8860 | Y29: 5755 | Z29: 9648 | AA29: 4334 | AB29: 4849 | AC29: 5154 | AD29: 4685 | AE29: 2902 | AF29: 1108 | AG29: 2418 | AH29: 3991 | AI29: 5132 | AJ29: 2073 | AK29: 3301 | AL29: 1163 | AM29: 654 | AN29: 988 | AO29: 215 | AP29: 296 | AQ29: 0
A30: 2026-02 | B30: 49180 | C30: 13176 | D30: 17555 | E30: 6281 | F30: 7471 | G30: 7262 | H30: 3648 | I30: 2119 | J30: 2976 | K30: 2020 | L30: 11098 | M30: 4634 | N30: 7765 | O30: 4816 | P30: 2719 | Q30: 2569 | R30: 7375 | S30: 2971 | T30: 2764 | U30: 1801 | V30: 4075 | W30: 2024 | X30: 10764 | Y30: 5645 | Z30: 9310 | AA30: 3326 | AB30: 3851 | AC30: 4632 | AD30: 3358 | AE30: 2705 | AF30: 1775 | AG30: 2315 | AH30: 3515 | AI30: 4992 | AJ30: 1585 | AK30: 1822 | AL30: 725 | AM30: 660 | AN30: 840 | AO30: 1004 | AP30: 0 | AQ30: 0
A31: 2026-03 | B31: 43881 | C31: 13283 | D31: 15198 | E31: 12370 | F31: 6811 | G31: 6743 | H31: 4096 | I31: 1882 | J31: 2485 | K31: 3236 | L31: 9078 | M31: 4029 | N31: 8030 | O31: 2700 | P31: 4474 | Q31: 3451 | R31: 6501 | S31: 3984 | T31: 2420 | U31: 1049 | V31: 3229 | W31: 1383 | X31: 12134 | Y31: 6618 | Z31: 12970 | AA31: 4368 | AB31: 2700 | AC31: 4384 | AD31: 2430 | AE31: 1844 | AF31: 1135 | AG31: 3121 | AH31: 3245 | AI31: 5869 | AJ31: 55 | AK31: 62 | AL31: 767 | AM31: 664 | AN31: 0 | AO31: 916 | AP31: 166 | AQ31: 0
A32: 2026-04 | B32: 44237 | C32: 14507 | D32: 16595 | E32: 5943 | F32: 6687 | G32: 6765 | H32: 3984 | I32: 2362 | J32: 2617 | K32: 3257 | L32: 9555 | M32: 3873 | N32: 8602 | O32: 2982 | P32: 3659 | Q32: 3816 | R32: 6794 | S32: 2645 | T32: 2487 | U32: 1872 | V32: 3671 | W32: 1684 | X32: 18378 | Y32: 6982 | Z32: 14364 | AA32: 5824 | AB32: 3075 | AC32: 4421 | AD32: 1641 | AE32: 2261 | AF32: 1275 | AG32: 6639 | AH32: 3200 | AI32: 3768 | AJ32: 56 | AK32: 59 | AL32: 648 | AM32: 885 | AN32: 0 | AO32: 525 | AP32: 0 | AQ32: 0
A33: 2026-05 | B33: 45996 | C33: 17134 | D33: 19884 | E33: 8675 | F33: 6896 | G33: 6760 | H33: 4818 | I33: 1863 | J33: 2303 | K33: 3230 | L33: 9669 | M33: 4635 | N33: 9562 | O33: 2720 | P33: 6257 | Q33: 7008 | R33: 7221 | S33: 2915 | T33: 2193 | U33: 1932 | V33: 3965 | W33: 2291 | X33: 18886 | Y33: 10312 | Z33: 14704 | AA33: 4894 | AB33: 4089 | AC33: 5912 | AD33: 1632 | AE33: 1296 | AF33: 1548 | AG33: 7547 | AH33: 3170 | AI33: 4230 | AJ33: 59 | AK33: 75 | AL33: 1598 | AM33: 404 | AN33: 0 | AO33: 0 | AP33: 21 | AQ33: 0
A34: 2026-06 | B34: 44430 | C34: 18099 | D34: 20693 | E34: 6275 | F34: 7737 | G34: 8678 | H34: 4604 | I34: 1973 | J34: 2264 | K34: 2369 | L34: 9764 | M34: 4685 | N34: 7729 | O34: 3648 | P34: 6104 | Q34: 3728 | R34: 6990 | S34: 3026 | T34: 2228 | U34: 1929 | V34: 4179 | W34: 1041 | X34: 21194 | Y34: 7368 | Z34: 14287 | AA34: 5881 | AB34: 4114 | AC34: 4100 | AD34: 2412 | AE34: 2238 | AF34: 2198 | AG34: 5234 | AH34: 2905 | AI34: 4594 | AJ34: 52 | AK34: 84 | AL34: 1114 | AM34: 373 | AN34: 0 | AO34: 980 | AP34: 199 | AQ34: 6
A35: 2026-07 | B35: 42911 | C35: 17317 | D35: 16449 | E35: 7760 | F35: 8871 | G35: 10415 | H35: 3822 | I35: 2231 | J35: 2862 | K35: 2380 | L35: 8834 | M35: 6245 | N35: 7660 | O35: 4417 | P35: 4685 | Q35: 5473 | R35: 6374 | S35: 2866 | T35: 2262 | U35: 2154 | V35: 4463 | W35: 1245 | X35: 19072 | Y35: 8893 | Z35: 12077 | AA35: 6216 | AB35: 3982 | AC35: 4858 | AD35: 2328 | AE35: 1967 | AF35: 2162 | AG35: 5881 | AH35: 2877 | AI35: 4523 | AJ35: 52 | AK35: 87 | AL35: 1503 | AM35: 658 | AN35: 0 | AO35: 261 | AP35: 0 | AQ35: 0
A36: 2026-08 | B36: 41679 | C36: 19328 | D36: 18455 | E36: 8216 | F36: 8539 | G36: 10193 | H36: 3802 | I36: 2427 | J36: 2808 | K36: 2831 | L36: 9157 | M36: 3342 | N36: 8579 | O36: 4580 | P36: 4476 | Q36: 3509 | R36: 6876 | S36: 3854 | T36: 2349 | U36: 4358 | V36: 3500 | W36: 1466 | X36: 18180 | Y36: 9195 | Z36: 13734 | AA36: 4371 | AB36: 4926 | AC36: 4314 | AD36: 1462 | AE36: 2489 | AF36: 2937 | AG36: 4191 | AH36: 4339 | AI36: 5854 | AJ36: 65 | AK36: 82 | AL36: 1044 | AM36: 659 | AN36: 0 | AO36: 1112 | AP36: 0 | AQ36: 0
... A40: Lead time (tuần) | B40: 2 | C40: 2 | D40: 2 | E40: 2 | F40: 2 | G40: 2 | H40: 2 | I40: 2 | J40: 2 | K40: 2 | L40: 3 | M40: 3 | N40: 3 | O40: 3 | P40: 3 | Q40: 3 | R40: 3 | S40: 3 | T40: 4 | U40: 4 | V40: 3 | W40: 3 | X40: 3 | Y40: 3 | Z40: 3 | AA40: 3 | AB40: 2 | AC40: 2 | AD40: 4 | AE40: 4 | AF40: 3 | AG40: 3 | AH40: 3 | AI40: 3 | AJ40: 8 | AK40: 8 | AL40: 3 | AM40: 3 | AN40: 10 | AO40: 3 | AP40: 3 | AQ40: 6

Sheet 01_Portfolio
A1: 01 · Portfolio của tôi
A2: Chọn chuỗi ở hàng 5 (ô vàng). Dữ liệu 36 tháng lấy tự động từ sheet Data bằng INDEX/MATCH.
A4: Họ tên / Portfolio
A5: Chuỗi
A6: Tháng | B6: Chuỗi 1 | C6: Chuỗi 2 | D6: Chuỗi 3 | E6: Chuỗi 4 | F6: Chuỗi 5 | G6: Chuỗi 6
A7: 2023-10 | B7: =IF(B$5="","",INDEX(Data!$B$2:$AQ$2,MATCH(B$5,Data!$B$1:$AQ$1,0))) | C7: =IF(C$5="","",INDEX(Data!$B$2:$AQ$2,MATCH(C$5,Data!$B$1:$AQ$1,0))) | D7: =IF(D$5="","",INDEX(Data!$B$2:$AQ$2,MATCH(D$5,Data!$B$1:$AQ$1,0))) | E7: =IF(E$5="","",INDEX(Data!$B$2:$AQ$2,MATCH(E$5,Data!$B$1:$AQ$1,0))) | F7: =IF(F$5="","",INDEX(Data!$B$2:$AQ$2,MATCH(F$5,Data!$B$1:$AQ$1,0))) | G7: =IF(G$5="","",INDEX(Data!$B$2:$AQ$2,MATCH(G$5,Data!$B$1:$AQ$1,0)))
A8: 2023-11 | B8: =IF(B$5="","",INDEX(Data!$B$3:$AQ$3,MATCH(B$5,Data!$B$1:$AQ$1,0))) | C8: =IF(C$5="","",INDEX(Data!$B$3:$AQ$3,MATCH(C$5,Data!$B$1:$AQ$1,0))) | D8: =IF(D$5="","",INDEX(Data!$B$3:$AQ$3,MATCH(D$5,Data!$B$1:$AQ$1,0))) | E8: =IF(E$5="","",INDEX(Data!$B$3:$AQ$3,MATCH(E$5,Data!$B$1:$AQ$1,0))) | F8: =IF(F$5="","",INDEX(Data!$B$3:$AQ$3,MATCH(F$5,Data!$B$1:$AQ$1,0))) | G8: =IF(G$5="","",INDEX(Data!$B$3:$AQ$3,MATCH(G$5,Data!$B$1:$AQ$1,0)))
A9: 2023-12 | B9: =IF(B$5="","",INDEX(Data!$B$4:$AQ$4,MATCH(B$5,Data!$B$1:$AQ$1,0))) | C9: =IF(C$5="","",INDEX(Data!$B$4:$AQ$4,MATCH(C$5,Data!$B$1:$AQ$1,0))) | D9: =IF(D$5="","",INDEX(Data!$B$4:$AQ$4,MATCH(D$5,Data!$B$1:$AQ$1,0))) | E9: =IF(E$5="","",INDEX(Data!$B$4:$AQ$4,MATCH(E$5,Data!$B$1:$AQ$1,0))) | F9: =IF(F$5="","",INDEX(Data!$B$4:$AQ$4,MATCH(F$5,Data!$B$1:$AQ$1,0))) | G9: =IF(G$5="","",INDEX(Data!$B$4:$AQ$4,MATCH(G$5,Data!$B$1:$AQ$1,0)))
A10: 2024-01 | B10: =IF(B$5="","",INDEX(Data!$B$5:$AQ$5,MATCH(B$5,Data!$B$1:$AQ$1,0))) | C10: =IF(C$5="","",INDEX(Data!$B$5:$AQ$5,MATCH(C$5,Data!$B$1:$AQ$1,0))) | D10: =IF(D$5="","",INDEX(Data!$B$5:$AQ$5,MATCH(D$5,Data!$B$1:$AQ$1,0))) | E10: =IF(E$5="","",INDEX(Data!$B$5:$AQ$5,MATCH(E$5,Data!$B$1:$AQ$1,0))) | F10: =IF(F$5="","",INDEX(Data!$B$5:$AQ$5,MATCH(F$5,Data!$B$1:$AQ$1,0))) | G10: =IF(G$5="","",INDEX(Data!$B$5:$AQ$5,MATCH(G$5,Data!$B$1:$AQ$1,0)))
A11: 2024-02 | B11: =IF(B$5="","",INDEX(Data!$B$6:$AQ$6,MATCH(B$5,Data!$B$1:$AQ$1,0))) | C11: =IF(C$5="","",INDEX(Data!$B$6:$AQ$6,MATCH(C$5,Data!$B$1:$AQ$1,0))) | D11: =IF(D$5="","",INDEX(Data!$B$6:$AQ$6,MATCH(D$5,Data!$B$1:$AQ$1,0))) | E11: =IF(E$5="","",INDEX(Data!$B$6:$AQ$6,MATCH(E$5,Data!$B$1:$AQ$1,0))) | F11: =IF(F$5="","",INDEX(Data!$B$6:$AQ$6,MATCH(F$5,Data!$B$1:$AQ$1,0))) | G11: =IF(G$5="","",INDEX(Data!$B$6:$AQ$6,MATCH(G$5,Data!$B$1:$AQ$1,0)))
A12: 2024-03 | B12: =IF(B$5="","",INDEX(Data!$B$7:$AQ$7,MATCH(B$5,Data!$B$1:$AQ$1,0))) | C12: =IF(C$5="","",INDEX(Data!$B$7:$AQ$7,MATCH(C$5,Data!$B$1:$AQ$1,0))) | D12: =IF(D$5="","",INDEX(Data!$B$7:$AQ$7,MATCH(D$5,Data!$B$1:$AQ$1,0))) | E12: =IF(E$5="","",INDEX(Data!$B$7:$AQ$7,MATCH(E$5,Data!$B$1:$AQ$1,0))) | F12: =IF(F$5="","",INDEX(Data!$B$7:$AQ$7,MATCH(F$5,Data!$B$1:$AQ$1,0))) | G12: =IF(G$5="","",INDEX(Data!$B$7:$AQ$7,MATCH(G$5,Data!$B$1:$AQ$1,0)))
A13: 2024-04 | B13: =IF(B$5="","",INDEX(Data!$B$8:$AQ$8,MATCH(B$5,Data!$B$1:$AQ$1,0))) | C13: =IF(C$5="","",INDEX(Data!$B$8:$AQ$8,MATCH(C$5,Data!$B$1:$AQ$1,0))) | D13: =IF(D$5="","",INDEX(Data!$B$8:$AQ$8,MATCH(D$5,Data!$B$1:$AQ$1,0))) | E13: =IF(E$5="","",INDEX(Data!$B$8:$AQ$8,MATCH(E$5,Data!$B$1:$AQ$1,0))) | F13: =IF(F$5="","",INDEX(Data!$B$8:$AQ$8,MATCH(F$5,Data!$B$1:$AQ$1,0))) | G13: =IF(G$5="","",INDEX(Data!$B$8:$AQ$8,MATCH(G$5,Data!$B$1:$AQ$1,0)))
A14: 2024-05 | B14: =IF(B$5="","",INDEX(Data!$B$9:$AQ$9,MATCH(B$5,Data!$B$1:$AQ$1,0))) | C14: =IF(C$5="","",INDEX(Data!$B$9:$AQ$9,MATCH(C$5,Data!$B$1:$AQ$1,0))) | D14: =IF(D$5="","",INDEX(Data!$B$9:$AQ$9,MATCH(D$5,Data!$B$1:$AQ$1,0))) | E14: =IF(E$5="","",INDEX(Data!$B$9:$AQ$9,MATCH(E$5,Data!$B$1:$AQ$1,0))) | F14: =IF(F$5="","",INDEX(Data!$B$9:$AQ$9,MATCH(F$5,Data!$B$1:$AQ$1,0))) | G14: =IF(G$5="","",INDEX(Data!$B$9:$AQ$9,MATCH(G$5,Data!$B$1:$AQ$1,0)))
A15: 2024-06 | B15: =IF(B$5="","",INDEX(Data!$B$10:$AQ$10,MATCH(B$5,Data!$B$1:$AQ$1,0))) | C15: =IF(C$5="","",INDEX(Data!$B$10:$AQ$10,MATCH(C$5,Data!$B$1:$AQ$1,0))) | D15: =IF(D$5="","",INDEX(Data!$B$10:$AQ$10,MATCH(D$5,Data!$B$1:$AQ$1,0))) | E15: =IF(E$5="","",INDEX(Data!$B$10:$AQ$10,MATCH(E$5,Data!$B$1:$AQ$1,0))) | F15: =IF(F$5="","",INDEX(Data!$B$10:$AQ$10,MATCH(F$5,Data!$B$1:$AQ$1,0))) | G15: =IF(G$5="","",INDEX(Data!$B$10:$AQ$10,MATCH(G$5,Data!$B$1:$AQ$1,0)))
A16: 2024-07 | B16: =IF(B$5="","",INDEX(Data!$B$11:$AQ$11,MATCH(B$5,Data!$B$1:$AQ$1,0))) | C16: =IF(C$5="","",INDEX(Data!$B$11:$AQ$11,MATCH(C$5,Data!$B$1:$AQ$1,0))) | D16: =IF(D$5="","",INDEX(Data!$B$11:$AQ$11,MATCH(D$5,Data!$B$1:$AQ$1,0))) | E16: =IF(E$5="","",INDEX(Data!$B$11:$AQ$11,MATCH(E$5,Data!$B$1:$AQ$1,0))) | F16: =IF(F$5="","",INDEX(Data!$B$11:$AQ$11,MATCH(F$5,Data!$B$1:$AQ$1,0))) | G16: =IF(G$5="","",INDEX(Data!$B$11:$AQ$11,MATCH(G$5,Data!$B$1:$AQ$1,0)))
A17: 2024-08 | B17: =IF(B$5="","",INDEX(Data!$B$12:$AQ$12,MATCH(B$5,Data!$B$1:$AQ$1,0))) | C17: =IF(C$5="","",INDEX(Data!$B$12:$AQ$12,MATCH(C$5,Data!$B$1:$AQ$1,0))) | D17: =IF(D$5="","",INDEX(Data!$B$12:$AQ$12,MATCH(D$5,Data!$B$1:$AQ$1,0))) | E17: =IF(E$5="","",INDEX(Data!$B$12:$AQ$12,MATCH(E$5,Data!$B$1:$AQ$1,0))) | F17: =IF(F$5="","",INDEX(Data!$B$12:$AQ$12,MATCH(F$5,Data!$B$1:$AQ$1,0))) | G17: =IF(G$5="","",INDEX(Data!$B$12:$AQ$12,MATCH(G$5,Data!$B$1:$AQ$1,0)))
A18: 2024-09 | B18: =IF(B$5="","",INDEX(Data!$B$13:$AQ$13,MATCH(B$5,Data!$B$1:$AQ$1,0))) | C18: =IF(C$5="","",INDEX(Data!$B$13:$AQ$13,MATCH(C$5,Data!$B$1:$AQ$1,0))) | D18: =IF(D$5="","",INDEX(Data!$B$13:$AQ$13,MATCH(D$5,Data!$B$1:$AQ$1,0))) | E18: =IF(E$5="","",INDEX(Data!$B$13:$AQ$13,MATCH(E$5,Data!$B$1:$AQ$1,0))) | F18: =IF(F$5="","",INDEX(Data!$B$13:$AQ$13,MATCH(F$5,Data!$B$1:$AQ$1,0))) | G18: =IF(G$5="","",INDEX(Data!$B$13:$AQ$13,MATCH(G$5,Data!$B$1:$AQ$1,0)))
A19: 2024-10 | B19: =IF(B$5="","",INDEX(Data!$B$14:$AQ$14,MATCH(B$5,Data!$B$1:$AQ$1,0))) | C19: =IF(C$5="","",INDEX(Data!$B$14:$AQ$14,MATCH(C$5,Data!$B$1:$AQ$1,0))) | D19: =IF(D$5="","",INDEX(Data!$B$14:$AQ$14,MATCH(D$5,Data!$B$1:$AQ$1,0))) | E19: =IF(E$5="","",INDEX(Data!$B$14:$AQ$14,MATCH(E$5,Data!$B$1:$AQ$1,0))) | F19: =IF(F$5="","",INDEX(Data!$B$14:$AQ$14,MATCH(F$5,Data!$B$1:$AQ$1,0))) | G19: =IF(G$5="","",INDEX(Data!$B$14:$AQ$14,MATCH(G$5,Data!$B$1:$AQ$1,0)))
A20: 2024-11 | B20: =IF(B$5="","",INDEX(Data!$B$15:$AQ$15,MATCH(B$5,Data!$B$1:$AQ$1,0))) | C20: =IF(C$5="","",INDEX(Data!$B$15:$AQ$15,MATCH(C$5,Data!$B$1:$AQ$1,0))) | D20: =IF(D$5="","",INDEX(Data!$B$15:$AQ$15,MATCH(D$5,Data!$B$1:$AQ$1,0))) | E20: =IF(E$5="","",INDEX(Data!$B$15:$AQ$15,MATCH(E$5,Data!$B$1:$AQ$1,0))) | F20: =IF(F$5="","",INDEX(Data!$B$15:$AQ$15,MATCH(F$5,Data!$B$1:$AQ$1,0))) | G20: =IF(G$5="","",INDEX(Data!$B$15:$AQ$15,MATCH(G$5,Data!$B$1:$AQ$1,0)))
A21: 2024-12 | B21: =IF(B$5="","",INDEX(Data!$B$16:$AQ$16,MATCH(B$5,Data!$B$1:$AQ$1,0))) | C21: =IF(C$5="","",INDEX(Data!$B$16:$AQ$16,MATCH(C$5,Data!$B$1:$AQ$1,0))) | D21: =IF(D$5="","",INDEX(Data!$B$16:$AQ$16,MATCH(D$5,Data!$B$1:$AQ$1,0))) | E21: =IF(E$5="","",INDEX(Data!$B$16:$AQ$16,MATCH(E$5,Data!$B$1:$AQ$1,0))) | F21: =IF(F$5="","",INDEX(Data!$B$16:$AQ$16,MATCH(F$5,Data!$B$1:$AQ$1,0))) | G21: =IF(G$5="","",INDEX(Data!$B$16:$AQ$16,MATCH(G$5,Data!$B$1:$AQ$1,0)))
A22: 2025-01 | B22: =IF(B$5="","",INDEX(Data!$B$17:$AQ$17,MATCH(B$5,Data!$B$1:$AQ$1,0))) | C22: =IF(C$5="","",INDEX(Data!$B$17:$AQ$17,MATCH(C$5,Data!$B$1:$AQ$1,0))) | D22: =IF(D$5="","",INDEX(Data!$B$17:$AQ$17,MATCH(D$5,Data!$B$1:$AQ$1,0))) | E22: =IF(E$5="","",INDEX(Data!$B$17:$AQ$17,MATCH(E$5,Data!$B$1:$AQ$1,0))) | F22: =IF(F$5="","",INDEX(Data!$B$17:$AQ$17,MATCH(F$5,Data!$B$1:$AQ$1,0))) | G22: =IF(G$5="","",INDEX(Data!$B$17:$AQ$17,MATCH(G$5,Data!$B$1:$AQ$1,0)))
A23: 2025-02 | B23: =IF(B$5="","",INDEX(Data!$B$18:$AQ$18,MATCH(B$5,Data!$B$1:$AQ$1,0))) | C23: =IF(C$5="","",INDEX(Data!$B$18:$AQ$18,MATCH(C$5,Data!$B$1:$AQ$1,0))) | D23: =IF(D$5="","",INDEX(Data!$B$18:$AQ$18,MATCH(D$5,Data!$B$1:$AQ$1,0))) | E23: =IF(E$5="","",INDEX(Data!$B$18:$AQ$18,MATCH(E$5,Data!$B$1:$AQ$1,0))) | F23: =IF(F$5="","",INDEX(Data!$B$18:$AQ$18,MATCH(F$5,Data!$B$1:$AQ$1,0))) | G23: =IF(G$5="","",INDEX(Data!$B$18:$AQ$18,MATCH(G$5,Data!$B$1:$AQ$1,0)))
A24: 2025-03 | B24: =IF(B$5="","",INDEX(Data!$B$19:$AQ$19,MATCH(B$5,Data!$B$1:$AQ$1,0))) | C24: =IF(C$5="","",INDEX(Data!$B$19:$AQ$19,MATCH(C$5,Data!$B$1:$AQ$1,0))) | D24: =IF(D$5="","",INDEX(Data!$B$19:$AQ$19,MATCH(D$5,Data!$B$1:$AQ$1,0))) | E24: =IF(E$5="","",INDEX(Data!$B$19:$AQ$19,MATCH(E$5,Data!$B$1:$AQ$1,0))) | F24: =IF(F$5="","",INDEX(Data!$B$19:$AQ$19,MATCH(F$5,Data!$B$1:$AQ$1,0))) | G24: =IF(G$5="","",INDEX(Data!$B$19:$AQ$19,MATCH(G$5,Data!$B$1:$AQ$1,0)))
A25: 2025-04 | B25: =IF(B$5="","",INDEX(Data!$B$20:$AQ$20,MATCH(B$5,Data!$B$1:$AQ$1,0))) | C25: =IF(C$5="","",INDEX(Data!$B$20:$AQ$20,MATCH(C$5,Data!$B$1:$AQ$1,0))) | D25: =IF(D$5="","",INDEX(Data!$B$20:$AQ$20,MATCH(D$5,Data!$B$1:$AQ$1,0))) | E25: =IF(E$5="","",INDEX(Data!$B$20:$AQ$20,MATCH(E$5,Data!$B$1:$AQ$1,0))) | F25: =IF(F$5="","",INDEX(Data!$B$20:$AQ$20,MATCH(F$5,Data!$B$1:$AQ$1,0))) | G25: =IF(G$5="","",INDEX(Data!$B$20:$AQ$20,MATCH(G$5,Data!$B$1:$AQ$1,0)))
A26: 2025-05 | B26: =IF(B$5="","",INDEX(Data!$B$21:$AQ$21,MATCH(B$5,Data!$B$1:$AQ$1,0))) | C26: =IF(C$5="","",INDEX(Data!$B$21:$AQ$21,MATCH(C$5,Data!$B$1:$AQ$1,0))) | D26: =IF(D$5="","",INDEX(Data!$B$21:$AQ$21,MATCH(D$5,Data!$B$1:$AQ$1,0))) | E26: =IF(E$5="","",INDEX(Data!$B$21:$AQ$21,MATCH(E$5,Data!$B$1:$AQ$1,0))) | F26: =IF(F$5="","",INDEX(Data!$B$21:$AQ$21,MATCH(F$5,Data!$B$1:$AQ$1,0))) | G26: =IF(G$5="","",INDEX(Data!$B$21:$AQ$21,MATCH(G$5,Data!$B$1:$AQ$1,0)))
A27: 2025-06 | B27: =IF(B$5="","",INDEX(Data!$B$22:$AQ$22,MATCH(B$5,Data!$B$1:$AQ$1,0))) | C27: =IF(C$5="","",INDEX(Data!$B$22:$AQ$22,MATCH(C$5,Data!$B$1:$AQ$1,0))) | D27: =IF(D$5="","",INDEX(Data!$B$22:$AQ$22,MATCH(D$5,Data!$B$1:$AQ$1,0))) | E27: =IF(E$5="","",INDEX(Data!$B$22:$AQ$22,MATCH(E$5,Data!$B$1:$AQ$1,0))) | F27: =IF(F$5="","",INDEX(Data!$B$22:$AQ$22,MATCH(F$5,Data!$B$1:$AQ$1,0))) | G27: =IF(G$5="","",INDEX(Data!$B$22:$AQ$22,MATCH(G$5,Data!$B$1:$AQ$1,0)))
A28: 2025-07 | B28: =IF(B$5="","",INDEX(Data!$B$23:$AQ$23,MATCH(B$5,Data!$B$1:$AQ$1,0))) | C28: =IF(C$5="","",INDEX(Data!$B$23:$AQ$23,MATCH(C$5,Data!$B$1:$AQ$1,0))) | D28: =IF(D$5="","",INDEX(Data!$B$23:$AQ$23,MATCH(D$5,Data!$B$1:$AQ$1,0))) | E28: =IF(E$5="","",INDEX(Data!$B$23:$AQ$23,MATCH(E$5,Data!$B$1:$AQ$1,0))) | F28: =IF(F$5="","",INDEX(Data!$B$23:$AQ$23,MATCH(F$5,Data!$B$1:$AQ$1,0))) | G28: =IF(G$5="","",INDEX(Data!$B$23:$AQ$23,MATCH(G$5,Data!$B$1:$AQ$1,0)))
A29: 2025-08 | B29: =IF(B$5="","",INDEX(Data!$B$24:$AQ$24,MATCH(B$5,Data!$B$1:$AQ$1,0))) | C29: =IF(C$5="","",INDEX(Data!$B$24:$AQ$24,MATCH(C$5,Data!$B$1:$AQ$1,0))) | D29: =IF(D$5="","",INDEX(Data!$B$24:$AQ$24,MATCH(D$5,Data!$B$1:$AQ$1,0))) | E29: =IF(E$5="","",INDEX(Data!$B$24:$AQ$24,MATCH(E$5,Data!$B$1:$AQ$1,0))) | F29: =IF(F$5="","",INDEX(Data!$B$24:$AQ$24,MATCH(F$5,Data!$B$1:$AQ$1,0))) | G29: =IF(G$5="","",INDEX(Data!$B$24:$AQ$24,MATCH(G$5,Data!$B$1:$AQ$1,0)))
A30: 2025-09 | B30: =IF(B$5="","",INDEX(Data!$B$25:$AQ$25,MATCH(B$5,Data!$B$1:$AQ$1,0))) | C30: =IF(C$5="","",INDEX(Data!$B$25:$AQ$25,MATCH(C$5,Data!$B$1:$AQ$1,0))) | D30: =IF(D$5="","",INDEX(Data!$B$25:$AQ$25,MATCH(D$5,Data!$B$1:$AQ$1,0))) | E30: =IF(E$5="","",INDEX(Data!$B$25:$AQ$25,MATCH(E$5,Data!$B$1:$AQ$1,0))) | F30: =IF(F$5="","",INDEX(Data!$B$25:$AQ$25,MATCH(F$5,Data!$B$1:$AQ$1,0))) | G30: =IF(G$5="","",INDEX(Data!$B$25:$AQ$25,MATCH(G$5,Data!$B$1:$AQ$1,0)))
A31: 2025-10 | B31: =IF(B$5="","",INDEX(Data!$B$26:$AQ$26,MATCH(B$5,Data!$B$1:$AQ$1,0))) | C31: =IF(C$5="","",INDEX(Data!$B$26:$AQ$26,MATCH(C$5,Data!$B$1:$AQ$1,0))) | D31: =IF(D$5="","",INDEX(Data!$B$26:$AQ$26,MATCH(D$5,Data!$B$1:$AQ$1,0))) | E31: =IF(E$5="","",INDEX(Data!$B$26:$AQ$26,MATCH(E$5,Data!$B$1:$AQ$1,0))) | F31: =IF(F$5="","",INDEX(Data!$B$26:$AQ$26,MATCH(F$5,Data!$B$1:$AQ$1,0))) | G31: =IF(G$5="","",INDEX(Data!$B$26:$AQ$26,MATCH(G$5,Data!$B$1:$AQ$1,0)))
A32: 2025-11 | B32: =IF(B$5="","",INDEX(Data!$B$27:$AQ$27,MATCH(B$5,Data!$B$1:$AQ$1,0))) | C32: =IF(C$5="","",INDEX(Data!$B$27:$AQ$27,MATCH(C$5,Data!$B$1:$AQ$1,0))) | D32: =IF(D$5="","",INDEX(Data!$B$27:$AQ$27,MATCH(D$5,Data!$B$1:$AQ$1,0))) | E32: =IF(E$5="","",INDEX(Data!$B$27:$AQ$27,MATCH(E$5,Data!$B$1:$AQ$1,0))) | F32: =IF(F$5="","",INDEX(Data!$B$27:$AQ$27,MATCH(F$5,Data!$B$1:$AQ$1,0))) | G32: =IF(G$5="","",INDEX(Data!$B$27:$AQ$27,MATCH(G$5,Data!$B$1:$AQ$1,0)))
A33: 2025-12 | B33: =IF(B$5="","",INDEX(Data!$B$28:$AQ$28,MATCH(B$5,Data!$B$1:$AQ$1,0))) | C33: =IF(C$5="","",INDEX(Data!$B$28:$AQ$28,MATCH(C$5,Data!$B$1:$AQ$1,0))) | D33: =IF(D$5="","",INDEX(Data!$B$28:$AQ$28,MATCH(D$5,Data!$B$1:$AQ$1,0))) | E33: =IF(E$5="","",INDEX(Data!$B$28:$AQ$28,MATCH(E$5,Data!$B$1:$AQ$1,0))) | F33: =IF(F$5="","",INDEX(Data!$B$28:$AQ$28,MATCH(F$5,Data!$B$1:$AQ$1,0))) | G33: =IF(G$5="","",INDEX(Data!$B$28:$AQ$28,MATCH(G$5,Data!$B$1:$AQ$1,0)))
A34: 2026-01 | B34: =IF(B$5="","",INDEX(Data!$B$29:$AQ$29,MATCH(B$5,Data!$B$1:$AQ$1,0))) | C34: =IF(C$5="","",INDEX(Data!$B$29:$AQ$29,MATCH(C$5,Data!$B$1:$AQ$1,0))) | D34: =IF(D$5="","",INDEX(Data!$B$29:$AQ$29,MATCH(D$5,Data!$B$1:$AQ$1,0))) | E34: =IF(E$5="","",INDEX(Data!$B$29:$AQ$29,MATCH(E$5,Data!$B$1:$AQ$1,0))) | F34: =IF(F$5="","",INDEX(Data!$B$29:$AQ$29,MATCH(F$5,Data!$B$1:$AQ$1,0))) | G34: =IF(G$5="","",INDEX(Data!$B$29:$AQ$29,MATCH(G$5,Data!$B$1:$AQ$1,0)))
A35: 2026-02 | B35: =IF(B$5="","",INDEX(Data!$B$30:$AQ$30,MATCH(B$5,Data!$B$1:$AQ$1,0))) | C35: =IF(C$5="","",INDEX(Data!$B$30:$AQ$30,MATCH(C$5,Data!$B$1:$AQ$1,0))) | D35: =IF(D$5="","",INDEX(Data!$B$30:$AQ$30,MATCH(D$5,Data!$B$1:$AQ$1,0))) | E35: =IF(E$5="","",INDEX(Data!$B$30:$AQ$30,MATCH(E$5,Data!$B$1:$AQ$1,0))) | F35: =IF(F$5="","",INDEX(Data!$B$30:$AQ$30,MATCH(F$5,Data!$B$1:$AQ$1,0))) | G35: =IF(G$5="","",INDEX(Data!$B$30:$AQ$30,MATCH(G$5,Data!$B$1:$AQ$1,0)))
A36: 2026-03 | B36: =IF(B$5="","",INDEX(Data!$B$31:$AQ$31,MATCH(B$5,Data!$B$1:$AQ$1,0))) | C36: =IF(C$5="","",INDEX(Data!$B$31:$AQ$31,MATCH(C$5,Data!$B$1:$AQ$1,0))) | D36: =IF(D$5="","",INDEX(Data!$B$31:$AQ$31,MATCH(D$5,Data!$B$1:$AQ$1,0))) | E36: =IF(E$5="","",INDEX(Data!$B$31:$AQ$31,MATCH(E$5,Data!$B$1:$AQ$1,0))) | F36: =IF(F$5="","",INDEX(Data!$B$31:$AQ$31,MATCH(F$5,Data!$B$1:$AQ$1,0))) | G36: =IF(G$5="","",INDEX(Data!$B$31:$AQ$31,MATCH(G$5,Data!$B$1:$AQ$1,0)))
A37: 2026-04 | B37: =IF(B$5="","",INDEX(Data!$B$32:$AQ$32,MATCH(B$5,Data!$B$1:$AQ$1,0))) | C37: =IF(C$5="","",INDEX(Data!$B$32:$AQ$32,MATCH(C$5,Data!$B$1:$AQ$1,0))) | D37: =IF(D$5="","",INDEX(Data!$B$32:$AQ$32,MATCH(D$5,Data!$B$1:$AQ$1,0))) | E37: =IF(E$5="","",INDEX(Data!$B$32:$AQ$32,MATCH(E$5,Data!$B$1:$AQ$1,0))) | F37: =IF(F$5="","",INDEX(Data!$B$32:$AQ$32,MATCH(F$5,Data!$B$1:$AQ$1,0))) | G37: =IF(G$5="","",INDEX(Data!$B$32:$AQ$32,MATCH(G$5,Data!$B$1:$AQ$1,0)))
A38: 2026-05 | B38: =IF(B$5="","",INDEX(Data!$B$33:$AQ$33,MATCH(B$5,Data!$B$1:$AQ$1,0))) | C38: =IF(C$5="","",INDEX(Data!$B$33:$AQ$33,MATCH(C$5,Data!$B$1:$AQ$1,0))) | D38: =IF(D$5="","",INDEX(Data!$B$33:$AQ$33,MATCH(D$5,Data!$B$1:$AQ$1,0))) | E38: =IF(E$5="","",INDEX(Data!$B$33:$AQ$33,MATCH(E$5,Data!$B$1:$AQ$1,0))) | F38: =IF(F$5="","",INDEX(Data!$B$33:$AQ$33,MATCH(F$5,Data!$B$1:$AQ$1,0))) | G38: =IF(G$5="","",INDEX(Data!$B$33:$AQ$33,MATCH(G$5,Data!$B$1:$AQ$1,0)))
A39: 2026-06 | B39: =IF(B$5="","",INDEX(Data!$B$34:$AQ$34,MATCH(B$5,Data!$B$1:$AQ$1,0))) | C39: =IF(C$5="","",INDEX(Data!$B$34:$AQ$34,MATCH(C$5,Data!$B$1:$AQ$1,0))) | D39: =IF(D$5="","",INDEX(Data!$B$34:$AQ$34,MATCH(D$5,Data!$B$1:$AQ$1,0))) | E39: =IF(E$5="","",INDEX(Data!$B$34:$AQ$34,MATCH(E$5,Data!$B$1:$AQ$1,0))) | F39: =IF(F$5="","",INDEX(Data!$B$34:$AQ$34,MATCH(F$5,Data!$B$1:$AQ$1,0))) | G39: =IF(G$5="","",INDEX(Data!$B$34:$AQ$34,MATCH(G$5,Data!$B$1:$AQ$1,0)))
A40: 2026-07 | B40: =IF(B$5="","",INDEX(Data!$B$35:$AQ$35,MATCH(B$5,Data!$B$1:$AQ$1,0))) | C40: =IF(C$5="","",INDEX(Data!$B$35:$AQ$35,MATCH(C$5,Data!$B$1:$AQ$1,0))) | D40: =IF(D$5="","",INDEX(Data!$B$35:$AQ$35,MATCH(D$5,Data!$B$1:$AQ$1,0))) | E40: =IF(E$5="","",INDEX(Data!$B$35:$AQ$35,MATCH(E$5,Data!$B$1:$AQ$1,0))) | F40: =IF(F$5="","",INDEX(Data!$B$35:$AQ$35,MATCH(F$5,Data!$B$1:$AQ$1,0))) | G40: =IF(G$5="","",INDEX(Data!$B$35:$AQ$35,MATCH(G$5,Data!$B$1:$AQ$1,0)))
A41: 2026-08 | B41: =IF(B$5="","",INDEX(Data!$B$36:$AQ$36,MATCH(B$5,Data!$B$1:$AQ$1,0))) | C41: =IF(C$5="","",INDEX(Data!$B$36:$AQ$36,MATCH(C$5,Data!$B$1:$AQ$1,0))) | D41: =IF(D$5="","",INDEX(Data!$B$36:$AQ$36,MATCH(D$5,Data!$B$1:$AQ$1,0))) | E41: =IF(E$5="","",INDEX(Data!$B$36:$AQ$36,MATCH(E$5,Data!$B$1:$AQ$1,0))) | F41: =IF(F$5="","",INDEX(Data!$B$36:$AQ$36,MATCH(F$5,Data!$B$1:$AQ$1,0))) | G41: =IF(G$5="","",INDEX(Data!$B$36:$AQ$36,MATCH(G$5,Data!$B$1:$AQ$1,0)))
...

Sheet 02_NhatKy_LamSach
A1: 02 · Nhật ký làm sạch dữ liệu
A2: Nếu dùng bản demand_clean của lớp: ghi lại những điều chỉnh đã có trong bản đó liên quan đến portfolio của bạn.
A4: Chuỗi | B4: Tháng | C4: Số gốc | D4: Số sau | E4: Quy tắc | F4: Lý do | G4: Bằng chứng

Sheet 03_ChonMoHinh
A1: 03 · Chọn mô hình bằng sai số ngoài mẫu (6 tháng test 04–09/2026)
A2: Mỗi chuỗi ≥ 3 phương pháp, gồm 1 mốc. Ghi phương pháp chọn ở cột F của dòng đầu mỗi chuỗi.
A4: Chuỗi | B4: Phương pháp | C4: WMAPE | D4: Bias% | E4: MASE | F4: Chọn? | G4: Lý do (ngắn)

Sheet 04_DuBao_12T
A1: 04 · Dự báo 12 tháng và số đồng thuận (CHƯA giới hạn năng lực)
A2: Đồng thuận = Thống kê + Điều chỉnh. Mỗi điều chỉnh ≠ 0 phải có mã giả định (sheet 05).
A4: Chuỗi | B4: Tháng | C4: Thống kê | D4: Điều chỉnh | E4: Đồng thuận | F4: Mã giả định | G4: Ghi chú
A5: =01_Portfolio!B$5 -> 0 | B5: 2026-10 | E5: =IF(C5="","",C5+N(D5))
A6: =01_Portfolio!B$5 -> 0 | B6: 2026-11 | E6: =IF(C6="","",C6+N(D6))
A7: =01_Portfolio!B$5 -> 0 | B7: 2026-12 | E7: =IF(C7="","",C7+N(D7))
A8: =01_Portfolio!B$5 -> 0 | B8: 2027-01 | E8: =IF(C8="","",C8+N(D8))
A9: =01_Portfolio!B$5 -> 0 | B9: 2027-02 | E9: =IF(C9="","",C9+N(D9))
A10: =01_Portfolio!B$5 -> 0 | B10: 2027-03 | E10: =IF(C10="","",C10+N(D10))
A11: =01_Portfolio!B$5 -> 0 | B11: 2027-04 | E11: =IF(C11="","",C11+N(D11))
A12: =01_Portfolio!B$5 -> 0 | B12: 2027-05 | E12: =IF(C12="","",C12+N(D12))
A13: =01_Portfolio!B$5 -> 0 | B13: 2027-06 | E13: =IF(C13="","",C13+N(D13))
A14: =01_Portfolio!B$5 -> 0 | B14: 2027-07 | E14: =IF(C14="","",C14+N(D14))
A15: =01_Portfolio!B$5 -> 0 | B15: 2027-08 | E15: =IF(C15="","",C15+N(D15))
A16: =01_Portfolio!B$5 -> 0 | B16: 2027-09 | E16: =IF(C16="","",C16+N(D16))
A17: =01_Portfolio!C$5 -> 0 | B17: 2026-10 | E17: =IF(C17="","",C17+N(D17))
A18: =01_Portfolio!C$5 -> 0 | B18: 2026-11 | E18: =IF(C18="","",C18+N(D18))
A19: =01_Portfolio!C$5 -> 0 | B19: 2026-12 | E19: =IF(C19="","",C19+N(D19))
A20: =01_Portfolio!C$5 -> 0 | B20: 2027-01 | E20: =IF(C20="","",C20+N(D20))
A21: =01_Portfolio!C$5 -> 0 | B21: 2027-02 | E21: =IF(C21="","",C21+N(D21))
A22: =01_Portfolio!C$5 -> 0 | B22: 2027-03 | E22: =IF(C22="","",C22+N(D22))
A23: =01_Portfolio!C$5 -> 0 | B23: 2027-04 | E23: =IF(C23="","",C23+N(D23))
A24: =01_Portfolio!C$5 -> 0 | B24: 2027-05 | E24: =IF(C24="","",C24+N(D24))
A25: =01_Portfolio!C$5 -> 0 | B25: 2027-06 | E25: =IF(C25="","",C25+N(D25))
A26: =01_Portfolio!C$5 -> 0 | B26: 2027-07 | E26: =IF(C26="","",C26+N(D26))
A27: =01_Portfolio!C$5 -> 0 | B27: 2027-08 | E27: =IF(C27="","",C27+N(D27))
A28: =01_Portfolio!C$5 -> 0 | B28: 2027-09 | E28: =IF(C28="","",C28+N(D28))
A29: =01_Portfolio!D$5 -> 0 | B29: 2026-10 | E29: =IF(C29="","",C29+N(D29))
A30: =01_Portfolio!D$5 -> 0 | B30: 2026-11 | E30: =IF(C30="","",C30+N(D30))
A31: =01_Portfolio!D$5 -> 0 | B31: 2026-12 | E31: =IF(C31="","",C31+N(D31))
A32: =01_Portfolio!D$5 -> 0 | B32: 2027-01 | E32: =IF(C32="","",C32+N(D32))
A33: =01_Portfolio!D$5 -> 0 | B33: 2027-02 | E33: =IF(C33="","",C33+N(D33))
A34: =01_Portfolio!D$5 -> 0 | B34: 2027-03 | E34: =IF(C34="","",C34+N(D34))
A35: =01_Portfolio!D$5 -> 0 | B35: 2027-04 | E35: =IF(C35="","",C35+N(D35))
A36: =01_Portfolio!D$5 -> 0 | B36: 2027-05 | E36: =IF(C36="","",C36+N(D36))
A37: =01_Portfolio!D$5 -> 0 | B37: 2027-06 | E37: =IF(C37="","",C37+N(D37))
A38: =01_Portfolio!D$5 -> 0 | B38: 2027-07 | E38: =IF(C38="","",C38+N(D38))
A39: =01_Portfolio!D$5 -> 0 | B39: 2027-08 | E39: =IF(C39="","",C39+N(D39))
A40: =01_Portfolio!D$5 -> 0 | B40: 2027-09 | E40: =IF(C40="","",C40+N(D40))
A41: =01_Portfolio!E$5 -> 0 | B41: 2026-10 | E41: =IF(C41="","",C41+N(D41))
...

Sheet 05_GiaDinh
A1: 05 · Nhật ký giả định
A2: Phân biệt rõ: dữ kiện lịch sử / nhận định thị trường / giả định lập kế hoạch.
A4: Mã | B4: Chuỗi | C4: Tháng | D4: Giả định | E4: Nguồn / bằng chứng | F4: Loại

Sheet 06_TonKho
A1: 06 · Tồn kho an toàn & ROP
A2: σ = RMSE dự báo 1 bước cuốn chiếu 12 tháng cuối (ngoài mẫu). Lead time lấy từ sku_master.
J4: Mức phục vụ | K4: 0.95
J5: z | K5: =NORMSINV(K4) -> 1.6448536
A7: Chuỗi | B7: σ sai số | C7: Lead time (tuần) | D7: L (tháng) | E7: z | F7: SS | G7: Dự báo T10 | H7: ROP
A8: =01_Portfolio!B$5 -> 0 | C8: =IF(A8=0,"",INDEX(Data!$B$40:$AQ$40,MATCH(A8,Data!$B$1:$AQ$1,0))) | D8: =IFERROR(C8/4.33,"") | E8: =$K$5 -> 1.6448536 | F8: =IFERROR(E8*B8*SQRT(D8),"") | G8: =IFERROR(INDEX(04_DuBao_12T!$E$5:$E$76,1),"") | H8: =IFERROR(G8*D8+F8,"")
A9: =01_Portfolio!C$5 -> 0 | C9: =IF(A9=0,"",INDEX(Data!$B$40:$AQ$40,MATCH(A9,Data!$B$1:$AQ$1,0))) | D9: =IFERROR(C9/4.33,"") | E9: =$K$5 -> 1.6448536 | F9: =IFERROR(E9*B9*SQRT(D9),"") | G9: =IFERROR(INDEX(04_DuBao_12T!$E$5:$E$76,13),"") | H9: =IFERROR(G9*D9+F9,"")
A10: =01_Portfolio!D$5 -> 0 | C10: =IF(A10=0,"",INDEX(Data!$B$40:$AQ$40,MATCH(A10,Data!$B$1:$AQ$1,0))) | D10: =IFERROR(C10/4.33,"") | E10: =$K$5 -> 1.6448536 | F10: =IFERROR(E10*B10*SQRT(D10),"") | G10: =IFERROR(INDEX(04_DuBao_12T!$E$5:$E$76,25),"") | H10: =IFERROR(G10*D10+F10,"")
A11: =01_Portfolio!E$5 -> 0 | C11: =IF(A11=0,"",INDEX(Data!$B$40:$AQ$40,MATCH(A11,Data!$B$1:$AQ$1,0))) | D11: =IFERROR(C11/4.33,"") | E11: =$K$5 -> 1.6448536 | F11: =IFERROR(E11*B11*SQRT(D11),"") | G11: =IFERROR(INDEX(04_DuBao_12T!$E$5:$E$76,37),"") | H11: =IFERROR(G11*D11+F11,"")
A12: =01_Portfolio!F$5 -> 0 | C12: =IF(A12=0,"",INDEX(Data!$B$40:$AQ$40,MATCH(A12,Data!$B$1:$AQ$1,0))) | D12: =IFERROR(C12/4.33,"") | E12: =$K$5 -> 1.6448536 | F12: =IFERROR(E12*B12*SQRT(D12),"") | G12: =IFERROR(INDEX(04_DuBao_12T!$E$5:$E$76,49),"") | H12: =IFERROR(G12*D12+F12,"")
A13: =01_Portfolio!G$5 -> 0 | C13: =IF(A13=0,"",INDEX(Data!$B$40:$AQ$40,MATCH(A13,Data!$B$1:$AQ$1,0))) | D13: =IFERROR(C13/4.33,"") | E13: =$K$5 -> 1.6448536 | F13: =IFERROR(E13*B13*SQRT(D13),"") | G13: =IFERROR(INDEX(04_DuBao_12T!$E$5:$E$76,61),"") | H13: =IFERROR(G13*D13+F13,"")

Sheet 07_BanGiao_PP
A1: 07 · Bàn giao cho module Production Planning
A2: Định dạng thống nhất với giảng viên Production Planning. Số = nhu cầu đồng thuận CHƯA giới hạn năng lực.
A4: Chuỗi | B4: Tháng | C4: Nhu cầu đồng thuận | D4: σ sai số | E4: Safety Stock | F4: Giả định / rủi ro
A5: =04_DuBao_12T!A5 -> 0 | B5: =04_DuBao_12T!B5 -> 2026-10 | C5: =04_DuBao_12T!E5 | D5: =06_TonKho!B8 -> 0 | E5: =06_TonKho!F8 | F5: =IF(04_DuBao_12T!F5="","",04_DuBao_12T!F5&" "&04_DuBao_12T!G5)
A6: =04_DuBao_12T!A6 -> 0 | B6: =04_DuBao_12T!B6 -> 2026-11 | C6: =04_DuBao_12T!E6 | D6: =06_TonKho!B8 -> 0 | E6: =06_TonKho!F8 | F6: =IF(04_DuBao_12T!F6="","",04_DuBao_12T!F6&" "&04_DuBao_12T!G6)
A7: =04_DuBao_12T!A7 -> 0 | B7: =04_DuBao_12T!B7 -> 2026-12 | C7: =04_DuBao_12T!E7 | D7: =06_TonKho!B8 -> 0 | E7: =06_TonKho!F8 | F7: =IF(04_DuBao_12T!F7="","",04_DuBao_12T!F7&" "&04_DuBao_12T!G7)
A8: =04_DuBao_12T!A8 -> 0 | B8: =04_DuBao_12T!B8 -> 2027-01 | C8: =04_DuBao_12T!E8 | D8: =06_TonKho!B8 -> 0 | E8: =06_TonKho!F8 | F8: =IF(04_DuBao_12T!F8="","",04_DuBao_12T!F8&" "&04_DuBao_12T!G8)
A9: =04_DuBao_12T!A9 -> 0 | B9: =04_DuBao_12T!B9 -> 2027-02 | C9: =04_DuBao_12T!E9 | D9: =06_TonKho!B8 -> 0 | E9: =06_TonKho!F8 | F9: =IF(04_DuBao_12T!F9="","",04_DuBao_12T!F9&" "&04_DuBao_12T!G9)
A10: =04_DuBao_12T!A10 -> 0 | B10: =04_DuBao_12T!B10 -> 2027-03 | C10: =04_DuBao_12T!E10 | D10: =06_TonKho!B8 -> 0 | E10: =06_TonKho!F8 | F10: =IF(04_DuBao_12T!F10="","",04_DuBao_12T!F10&" "&04_DuBao_12T!G10)
A11: =04_DuBao_12T!A11 -> 0 | B11: =04_DuBao_12T!B11 -> 2027-04 | C11: =04_DuBao_12T!E11 | D11: =06_TonKho!B8 -> 0 | E11: =06_TonKho!F8 | F11: =IF(04_DuBao_12T!F11="","",04_DuBao_12T!F11&" "&04_DuBao_12T!G11)
A12: =04_DuBao_12T!A12 -> 0 | B12: =04_DuBao_12T!B12 -> 2027-05 | C12: =04_DuBao_12T!E12 | D12: =06_TonKho!B8 -> 0 | E12: =06_TonKho!F8 | F12: =IF(04_DuBao_12T!F12="","",04_DuBao_12T!F12&" "&04_DuBao_12T!G12)
A13: =04_DuBao_12T!A13 -> 0 | B13: =04_DuBao_12T!B13 -> 2027-06 | C13: =04_DuBao_12T!E13 | D13: =06_TonKho!B8 -> 0 | E13: =06_TonKho!F8 | F13: =IF(04_DuBao_12T!F13="","",04_DuBao_12T!F13&" "&04_DuBao_12T!G13)
A14: =04_DuBao_12T!A14 -> 0 | B14: =04_DuBao_12T!B14 -> 2027-07 | C14: =04_DuBao_12T!E14 | D14: =06_TonKho!B8 -> 0 | E14: =06_TonKho!F8 | F14: =IF(04_DuBao_12T!F14="","",04_DuBao_12T!F14&" "&04_DuBao_12T!G14)
A15: =04_DuBao_12T!A15 -> 0 | B15: =04_DuBao_12T!B15 -> 2027-08 | C15: =04_DuBao_12T!E15 | D15: =06_TonKho!B8 -> 0 | E15: =06_TonKho!F8 | F15: =IF(04_DuBao_12T!F15="","",04_DuBao_12T!F15&" "&04_DuBao_12T!G15)
A16: =04_DuBao_12T!A16 -> 0 | B16: =04_DuBao_12T!B16 -> 2027-09 | C16: =04_DuBao_12T!E16 | D16: =06_TonKho!B8 -> 0 | E16: =06_TonKho!F8 | F16: =IF(04_DuBao_12T!F16="","",04_DuBao_12T!F16&" "&04_DuBao_12T!G16)
A17: =04_DuBao_12T!A17 -> 0 | B17: =04_DuBao_12T!B17 -> 2026-10 | C17: =04_DuBao_12T!E17 | D17: =06_TonKho!B9 -> 0 | E17: =06_TonKho!F9 | F17: =IF(04_DuBao_12T!F17="","",04_DuBao_12T!F17&" "&04_DuBao_12T!G17)
A18: =04_DuBao_12T!A18 -> 0 | B18: =04_DuBao_12T!B18 -> 2026-11 | C18: =04_DuBao_12T!E18 | D18: =06_TonKho!B9 -> 0 | E18: =06_TonKho!F9 | F18: =IF(04_DuBao_12T!F18="","",04_DuBao_12T!F18&" "&04_DuBao_12T!G18)
A19: =04_DuBao_12T!A19 -> 0 | B19: =04_DuBao_12T!B19 -> 2026-12 | C19: =04_DuBao_12T!E19 | D19: =06_TonKho!B9 -> 0 | E19: =06_TonKho!F9 | F19: =IF(04_DuBao_12T!F19="","",04_DuBao_12T!F19&" "&04_DuBao_12T!G19)
A20: =04_DuBao_12T!A20 -> 0 | B20: =04_DuBao_12T!B20 -> 2027-01 | C20: =04_DuBao_12T!E20 | D20: =06_TonKho!B9 -> 0 | E20: =06_TonKho!F9 | F20: =IF(04_DuBao_12T!F20="","",04_DuBao_12T!F20&" "&04_DuBao_12T!G20)
A21: =04_DuBao_12T!A21 -> 0 | B21: =04_DuBao_12T!B21 -> 2027-02 | C21: =04_DuBao_12T!E21 | D21: =06_TonKho!B9 -> 0 | E21: =06_TonKho!F9 | F21: =IF(04_DuBao_12T!F21="","",04_DuBao_12T!F21&" "&04_DuBao_12T!G21)
A22: =04_DuBao_12T!A22 -> 0 | B22: =04_DuBao_12T!B22 -> 2027-03 | C22: =04_DuBao_12T!E22 | D22: =06_TonKho!B9 -> 0 | E22: =06_TonKho!F9 | F22: =IF(04_DuBao_12T!F22="","",04_DuBao_12T!F22&" "&04_DuBao_12T!G22)
A23: =04_DuBao_12T!A23 -> 0 | B23: =04_DuBao_12T!B23 -> 2027-04 | C23: =04_DuBao_12T!E23 | D23: =06_TonKho!B9 -> 0 | E23: =06_TonKho!F9 | F23: =IF(04_DuBao_12T!F23="","",04_DuBao_12T!F23&" "&04_DuBao_12T!G23)
A24: =04_DuBao_12T!A24 -> 0 | B24: =04_DuBao_12T!B24 -> 2027-05 | C24: =04_DuBao_12T!E24 | D24: =06_TonKho!B9 -> 0 | E24: =06_TonKho!F9 | F24: =IF(04_DuBao_12T!F24="","",04_DuBao_12T!F24&" "&04_DuBao_12T!G24)
A25: =04_DuBao_12T!A25 -> 0 | B25: =04_DuBao_12T!B25 -> 2027-06 | C25: =04_DuBao_12T!E25 | D25: =06_TonKho!B9 -> 0 | E25: =06_TonKho!F9 | F25: =IF(04_DuBao_12T!F25="","",04_DuBao_12T!F25&" "&04_DuBao_12T!G25)
A26: =04_DuBao_12T!A26 -> 0 | B26: =04_DuBao_12T!B26 -> 2027-07 | C26: =04_DuBao_12T!E26 | D26: =06_TonKho!B9 -> 0 | E26: =06_TonKho!F9 | F26: =IF(04_DuBao_12T!F26="","",04_DuBao_12T!F26&" "&04_DuBao_12T!G26)
A27: =04_DuBao_12T!A27 -> 0 | B27: =04_DuBao_12T!B27 -> 2027-08 | C27: =04_DuBao_12T!E27 | D27: =06_TonKho!B9 -> 0 | E27: =06_TonKho!F9 | F27: =IF(04_DuBao_12T!F27="","",04_DuBao_12T!F27&" "&04_DuBao_12T!G27)
A28: =04_DuBao_12T!A28 -> 0 | B28: =04_DuBao_12T!B28 -> 2027-09 | C28: =04_DuBao_12T!E28 | D28: =06_TonKho!B9 -> 0 | E28: =06_TonKho!F9 | F28: =IF(04_DuBao_12T!F28="","",04_DuBao_12T!F28&" "&04_DuBao_12T!G28)
A29: =04_DuBao_12T!A29 -> 0 | B29: =04_DuBao_12T!B29 -> 2026-10 | C29: =04_DuBao_12T!E29 | D29: =06_TonKho!B10 -> 0 | E29: =06_TonKho!F10 | F29: =IF(04_DuBao_12T!F29="","",04_DuBao_12T!F29&" "&04_DuBao_12T!G29)
A30: =04_DuBao_12T!A30 -> 0 | B30: =04_DuBao_12T!B30 -> 2026-11 | C30: =04_DuBao_12T!E30 | D30: =06_TonKho!B10 -> 0 | E30: =06_TonKho!F10 | F30: =IF(04_DuBao_12T!F30="","",04_DuBao_12T!F30&" "&04_DuBao_12T!G30)
A31: =04_DuBao_12T!A31 -> 0 | B31: =04_DuBao_12T!B31 -> 2026-12 | C31: =04_DuBao_12T!E31 | D31: =06_TonKho!B10 -> 0 | E31: =06_TonKho!F10 | F31: =IF(04_DuBao_12T!F31="","",04_DuBao_12T!F31&" "&04_DuBao_12T!G31)
A32: =04_DuBao_12T!A32 -> 0 | B32: =04_DuBao_12T!B32 -> 2027-01 | C32: =04_DuBao_12T!E32 | D32: =06_TonKho!B10 -> 0 | E32: =06_TonKho!F10 | F32: =IF(04_DuBao_12T!F32="","",04_DuBao_12T!F32&" "&04_DuBao_12T!G32)
A33: =04_DuBao_12T!A33 -> 0 | B33: =04_DuBao_12T!B33 -> 2027-02 | C33: =04_DuBao_12T!E33 | D33: =06_TonKho!B10 -> 0 | E33: =06_TonKho!F10 | F33: =IF(04_DuBao_12T!F33="","",04_DuBao_12T!F33&" "&04_DuBao_12T!G33)
A34: =04_DuBao_12T!A34 -> 0 | B34: =04_DuBao_12T!B34 -> 2027-03 | C34: =04_DuBao_12T!E34 | D34: =06_TonKho!B10 -> 0 | E34: =06_TonKho!F10 | F34: =IF(04_DuBao_12T!F34="","",04_DuBao_12T!F34&" "&04_DuBao_12T!G34)
A35: =04_DuBao_12T!A35 -> 0 | B35: =04_DuBao_12T!B35 -> 2027-04 | C35: =04_DuBao_12T!E35 | D35: =06_TonKho!B10 -> 0 | E35: =06_TonKho!F10 | F35: =IF(04_DuBao_12T!F35="","",04_DuBao_12T!F35&" "&04_DuBao_12T!G35)
A36: =04_DuBao_12T!A36 -> 0 | B36: =04_DuBao_12T!B36 -> 2027-05 | C36: =04_DuBao_12T!E36 | D36: =06_TonKho!B10 -> 0 | E36: =06_TonKho!F10 | F36: =IF(04_DuBao_12T!F36="","",04_DuBao_12T!F36&" "&04_DuBao_12T!G36)
A37: =04_DuBao_12T!A37 -> 0 | B37: =04_DuBao_12T!B37 -> 2027-06 | C37: =04_DuBao_12T!E37 | D37: =06_TonKho!B10 -> 0 | E37: =06_TonKho!F10 | F37: =IF(04_DuBao_12T!F37="","",04_DuBao_12T!F37&" "&04_DuBao_12T!G37)
A38: =04_DuBao_12T!A38 -> 0 | B38: =04_DuBao_12T!B38 -> 2027-07 | C38: =04_DuBao_12T!E38 | D38: =06_TonKho!B10 -> 0 | E38: =06_TonKho!F10 | F38: =IF(04_DuBao_12T!F38="","",04_DuBao_12T!F38&" "&04_DuBao_12T!G38)
A39: =04_DuBao_12T!A39 -> 0 | B39: =04_DuBao_12T!B39 -> 2027-08 | C39: =04_DuBao_12T!E39 | D39: =06_TonKho!B10 -> 0 | E39: =06_TonKho!F10 | F39: =IF(04_DuBao_12T!F39="","",04_DuBao_12T!F39&" "&04_DuBao_12T!G39)
A40: =04_DuBao_12T!A40 -> 0 | B40: =04_DuBao_12T!B40 -> 2027-09 | C40: =04_DuBao_12T!E40 | D40: =06_TonKho!B10 -> 0 | E40: =06_TonKho!F10 | F40: =IF(04_DuBao_12T!F40="","",04_DuBao_12T!F40&" "&04_DuBao_12T!G40)
A41: =04_DuBao_12T!A41 -> 0 | B41: =04_DuBao_12T!B41 -> 2026-10 | C41: =04_DuBao_12T!E41 | D41: =06_TonKho!B11 -> 0 | E41: =06_TonKho!F11 | F41: =IF(04_DuBao_12T!F41="","",04_DuBao_12T!F41&" "&04_DuBao_12T!G41)
...

Sheet 08_SOP_1Trang
A1: 08 · Tóm tắt S&OP 1 trang
A2: Doanh thu theo giá NPP (triệu đồng). Viết 3 rủi ro/cơ hội và quyết định cần lãnh đạo chốt.
A4: Chuỗi | B4: 2026-10 | C4: 2026-11 | D4: 2026-12 | E4: 2027-01 | F4: 2027-02 | G4: 2027-03 | H4: 2027-04 | I4: 2027-05 | J4: 2027-06 | K4: 2027-07 | L4: 2027-08 | M4: 2027-09 | N4: Tổng 12T
A5: =01_Portfolio!B$5 -> 0 | B5: =IFERROR(04_DuBao_12T!$E$5*INDEX(Data!$B$39:$AQ$39,MATCH($A5,Data!$B$1:$AQ$1,0))/1000,"") | C5: =IFERROR(04_DuBao_12T!$E$6*INDEX(Data!$B$39:$AQ$39,MATCH($A5,Data!$B$1:$AQ$1,0))/1000,"") | D5: =IFERROR(04_DuBao_12T!$E$7*INDEX(Data!$B$39:$AQ$39,MATCH($A5,Data!$B$1:$AQ$1,0))/1000,"") | E5: =IFERROR(04_DuBao_12T!$E$8*INDEX(Data!$B$39:$AQ$39,MATCH($A5,Data!$B$1:$AQ$1,0))/1000,"") | F5: =IFERROR(04_DuBao_12T!$E$9*INDEX(Data!$B$39:$AQ$39,MATCH($A5,Data!$B$1:$AQ$1,0))/1000,"") | G5: =IFERROR(04_DuBao_12T!$E$10*INDEX(Data!$B$39:$AQ$39,MATCH($A5,Data!$B$1:$AQ$1,0))/1000,"") | H5: =IFERROR(04_DuBao_12T!$E$11*INDEX(Data!$B$39:$AQ$39,MATCH($A5,Data!$B$1:$AQ$1,0))/1000,"") | I5: =IFERROR(04_DuBao_12T!$E$12*INDEX(Data!$B$39:$AQ$39,MATCH($A5,Data!$B$1:$AQ$1,0))/1000,"") | J5: =IFERROR(04_DuBao_12T!$E$13*INDEX(Data!$B$39:$AQ$39,MATCH($A5,Data!$B$1:$AQ$1,0))/1000,"") | K5: =IFERROR(04_DuBao_12T!$E$14*INDEX(Data!$B$39:$AQ$39,MATCH($A5,Data!$B$1:$AQ$1,0))/1000,"") | L5: =IFERROR(04_DuBao_12T!$E$15*INDEX(Data!$B$39:$AQ$39,MATCH($A5,Data!$B$1:$AQ$1,0))/1000,"") | M5: =IFERROR(04_DuBao_12T!$E$16*INDEX(Data!$B$39:$AQ$39,MATCH($A5,Data!$B$1:$AQ$1,0))/1000,"") | N5: =SUM(B5:M5) -> 0
A6: =01_Portfolio!C$5 -> 0 | B6: =IFERROR(04_DuBao_12T!$E$17*INDEX(Data!$B$39:$AQ$39,MATCH($A6,Data!$B$1:$AQ$1,0))/1000,"") | C6: =IFERROR(04_DuBao_12T!$E$18*INDEX(Data!$B$39:$AQ$39,MATCH($A6,Data!$B$1:$AQ$1,0))/1000,"") | D6: =IFERROR(04_DuBao_12T!$E$19*INDEX(Data!$B$39:$AQ$39,MATCH($A6,Data!$B$1:$AQ$1,0))/1000,"") | E6: =IFERROR(04_DuBao_12T!$E$20*INDEX(Data!$B$39:$AQ$39,MATCH($A6,Data!$B$1:$AQ$1,0))/1000,"") | F6: =IFERROR(04_DuBao_12T!$E$21*INDEX(Data!$B$39:$AQ$39,MATCH($A6,Data!$B$1:$AQ$1,0))/1000,"") | G6: =IFERROR(04_DuBao_12T!$E$22*INDEX(Data!$B$39:$AQ$39,MATCH($A6,Data!$B$1:$AQ$1,0))/1000,"") | H6: =IFERROR(04_DuBao_12T!$E$23*INDEX(Data!$B$39:$AQ$39,MATCH($A6,Data!$B$1:$AQ$1,0))/1000,"") | I6: =IFERROR(04_DuBao_12T!$E$24*INDEX(Data!$B$39:$AQ$39,MATCH($A6,Data!$B$1:$AQ$1,0))/1000,"") | J6: =IFERROR(04_DuBao_12T!$E$25*INDEX(Data!$B$39:$AQ$39,MATCH($A6,Data!$B$1:$AQ$1,0))/1000,"") | K6: =IFERROR(04_DuBao_12T!$E$26*INDEX(Data!$B$39:$AQ$39,MATCH($A6,Data!$B$1:$AQ$1,0))/1000,"") | L6: =IFERROR(04_DuBao_12T!$E$27*INDEX(Data!$B$39:$AQ$39,MATCH($A6,Data!$B$1:$AQ$1,0))/1000,"") | M6: =IFERROR(04_DuBao_12T!$E$28*INDEX(Data!$B$39:$AQ$39,MATCH($A6,Data!$B$1:$AQ$1,0))/1000,"") | N6: =SUM(B6:M6) -> 0
A7: =01_Portfolio!D$5 -> 0 | B7: =IFERROR(04_DuBao_12T!$E$29*INDEX(Data!$B$39:$AQ$39,MATCH($A7,Data!$B$1:$AQ$1,0))/1000,"") | C7: =IFERROR(04_DuBao_12T!$E$30*INDEX(Data!$B$39:$AQ$39,MATCH($A7,Data!$B$1:$AQ$1,0))/1000,"") | D7: =IFERROR(04_DuBao_12T!$E$31*INDEX(Data!$B$39:$AQ$39,MATCH($A7,Data!$B$1:$AQ$1,0))/1000,"") | E7: =IFERROR(04_DuBao_12T!$E$32*INDEX(Data!$B$39:$AQ$39,MATCH($A7,Data!$B$1:$AQ$1,0))/1000,"") | F7: =IFERROR(04_DuBao_12T!$E$33*INDEX(Data!$B$39:$AQ$39,MATCH($A7,Data!$B$1:$AQ$1,0))/1000,"") | G7: =IFERROR(04_DuBao_12T!$E$34*INDEX(Data!$B$39:$AQ$39,MATCH($A7,Data!$B$1:$AQ$1,0))/1000,"") | H7: =IFERROR(04_DuBao_12T!$E$35*INDEX(Data!$B$39:$AQ$39,MATCH($A7,Data!$B$1:$AQ$1,0))/1000,"") | I7: =IFERROR(04_DuBao_12T!$E$36*INDEX(Data!$B$39:$AQ$39,MATCH($A7,Data!$B$1:$AQ$1,0))/1000,"") | J7: =IFERROR(04_DuBao_12T!$E$37*INDEX(Data!$B$39:$AQ$39,MATCH($A7,Data!$B$1:$AQ$1,0))/1000,"") | K7: =IFERROR(04_DuBao_12T!$E$38*INDEX(Data!$B$39:$AQ$39,MATCH($A7,Data!$B$1:$AQ$1,0))/1000,"") | L7: =IFERROR(04_DuBao_12T!$E$39*INDEX(Data!$B$39:$AQ$39,MATCH($A7,Data!$B$1:$AQ$1,0))/1000,"") | M7: =IFERROR(04_DuBao_12T!$E$40*INDEX(Data!$B$39:$AQ$39,MATCH($A7,Data!$B$1:$AQ$1,0))/1000,"") | N7: =SUM(B7:M7) -> 0
A8: =01_Portfolio!E$5 -> 0 | B8: =IFERROR(04_DuBao_12T!$E$41*INDEX(Data!$B$39:$AQ$39,MATCH($A8,Data!$B$1:$AQ$1,0))/1000,"") | C8: =IFERROR(04_DuBao_12T!$E$42*INDEX(Data!$B$39:$AQ$39,MATCH($A8,Data!$B$1:$AQ$1,0))/1000,"") | D8: =IFERROR(04_DuBao_12T!$E$43*INDEX(Data!$B$39:$AQ$39,MATCH($A8,Data!$B$1:$AQ$1,0))/1000,"") | E8: =IFERROR(04_DuBao_12T!$E$44*INDEX(Data!$B$39:$AQ$39,MATCH($A8,Data!$B$1:$AQ$1,0))/1000,"") | F8: =IFERROR(04_DuBao_12T!$E$45*INDEX(Data!$B$39:$AQ$39,MATCH($A8,Data!$B$1:$AQ$1,0))/1000,"") | G8: =IFERROR(04_DuBao_12T!$E$46*INDEX(Data!$B$39:$AQ$39,MATCH($A8,Data!$B$1:$AQ$1,0))/1000,"") | H8: =IFERROR(04_DuBao_12T!$E$47*INDEX(Data!$B$39:$AQ$39,MATCH($A8,Data!$B$1:$AQ$1,0))/1000,"") | I8: =IFERROR(04_DuBao_12T!$E$48*INDEX(Data!$B$39:$AQ$39,MATCH($A8,Data!$B$1:$AQ$1,0))/1000,"") | J8: =IFERROR(04_DuBao_12T!$E$49*INDEX(Data!$B$39:$AQ$39,MATCH($A8,Data!$B$1:$AQ$1,0))/1000,"") | K8: =IFERROR(04_DuBao_12T!$E$50*INDEX(Data!$B$39:$AQ$39,MATCH($A8,Data!$B$1:$AQ$1,0))/1000,"") | L8: =IFERROR(04_DuBao_12T!$E$51*INDEX(Data!$B$39:$AQ$39,MATCH($A8,Data!$B$1:$AQ$1,0))/1000,"") | M8: =IFERROR(04_DuBao_12T!$E$52*INDEX(Data!$B$39:$AQ$39,MATCH($A8,Data!$B$1:$AQ$1,0))/1000,"") | N8: =SUM(B8:M8) -> 0
A9: =01_Portfolio!F$5 -> 0 | B9: =IFERROR(04_DuBao_12T!$E$53*INDEX(Data!$B$39:$AQ$39,MATCH($A9,Data!$B$1:$AQ$1,0))/1000,"") | C9: =IFERROR(04_DuBao_12T!$E$54*INDEX(Data!$B$39:$AQ$39,MATCH($A9,Data!$B$1:$AQ$1,0))/1000,"") | D9: =IFERROR(04_DuBao_12T!$E$55*INDEX(Data!$B$39:$AQ$39,MATCH($A9,Data!$B$1:$AQ$1,0))/1000,"") | E9: =IFERROR(04_DuBao_12T!$E$56*INDEX(Data!$B$39:$AQ$39,MATCH($A9,Data!$B$1:$AQ$1,0))/1000,"") | F9: =IFERROR(04_DuBao_12T!$E$57*INDEX(Data!$B$39:$AQ$39,MATCH($A9,Data!$B$1:$AQ$1,0))/1000,"") | G9: =IFERROR(04_DuBao_12T!$E$58*INDEX(Data!$B$39:$AQ$39,MATCH($A9,Data!$B$1:$AQ$1,0))/1000,"") | H9: =IFERROR(04_DuBao_12T!$E$59*INDEX(Data!$B$39:$AQ$39,MATCH($A9,Data!$B$1:$AQ$1,0))/1000,"") | I9: =IFERROR(04_DuBao_12T!$E$60*INDEX(Data!$B$39:$AQ$39,MATCH($A9,Data!$B$1:$AQ$1,0))/1000,"") | J9: =IFERROR(04_DuBao_12T!$E$61*INDEX(Data!$B$39:$AQ$39,MATCH($A9,Data!$B$1:$AQ$1,0))/1000,"") | K9: =IFERROR(04_DuBao_12T!$E$62*INDEX(Data!$B$39:$AQ$39,MATCH($A9,Data!$B$1:$AQ$1,0))/1000,"") | L9: =IFERROR(04_DuBao_12T!$E$63*INDEX(Data!$B$39:$AQ$39,MATCH($A9,Data!$B$1:$AQ$1,0))/1000,"") | M9: =IFERROR(04_DuBao_12T!$E$64*INDEX(Data!$B$39:$AQ$39,MATCH($A9,Data!$B$1:$AQ$1,0))/1000,"") | N9: =SUM(B9:M9) -> 0
A10: =01_Portfolio!G$5 -> 0 | B10: =IFERROR(04_DuBao_12T!$E$65*INDEX(Data!$B$39:$AQ$39,MATCH($A10,Data!$B$1:$AQ$1,0))/1000,"") | C10: =IFERROR(04_DuBao_12T!$E$66*INDEX(Data!$B$39:$AQ$39,MATCH($A10,Data!$B$1:$AQ$1,0))/1000,"") | D10: =IFERROR(04_DuBao_12T!$E$67*INDEX(Data!$B$39:$AQ$39,MATCH($A10,Data!$B$1:$AQ$1,0))/1000,"") | E10: =IFERROR(04_DuBao_12T!$E$68*INDEX(Data!$B$39:$AQ$39,MATCH($A10,Data!$B$1:$AQ$1,0))/1000,"") | F10: =IFERROR(04_DuBao_12T!$E$69*INDEX(Data!$B$39:$AQ$39,MATCH($A10,Data!$B$1:$AQ$1,0))/1000,"") | G10: =IFERROR(04_DuBao_12T!$E$70*INDEX(Data!$B$39:$AQ$39,MATCH($A10,Data!$B$1:$AQ$1,0))/1000,"") | H10: =IFERROR(04_DuBao_12T!$E$71*INDEX(Data!$B$39:$AQ$39,MATCH($A10,Data!$B$1:$AQ$1,0))/1000,"") | I10: =IFERROR(04_DuBao_12T!$E$72*INDEX(Data!$B$39:$AQ$39,MATCH($A10,Data!$B$1:$AQ$1,0))/1000,"") | J10: =IFERROR(04_DuBao_12T!$E$73*INDEX(Data!$B$39:$AQ$39,MATCH($A10,Data!$B$1:$AQ$1,0))/1000,"") | K10: =IFERROR(04_DuBao_12T!$E$74*INDEX(Data!$B$39:$AQ$39,MATCH($A10,Data!$B$1:$AQ$1,0))/1000,"") | L10: =IFERROR(04_DuBao_12T!$E$75*INDEX(Data!$B$39:$AQ$39,MATCH($A10,Data!$B$1:$AQ$1,0))/1000,"") | M10: =IFERROR(04_DuBao_12T!$E$76*INDEX(Data!$B$39:$AQ$39,MATCH($A10,Data!$B$1:$AQ$1,0))/1000,"") | N10: =SUM(B10:M10) -> 0
A11: Tổng | B11: =SUM(B5:B10) -> 0 | C11: =SUM(C5:C10) -> 0 | D11: =SUM(D5:D10) -> 0 | E11: =SUM(E5:E10) -> 0 | F11: =SUM(F5:F10) -> 0 | G11: =SUM(G5:G10) -> 0 | H11: =SUM(H5:H10) -> 0 | I11: =SUM(I5:I10) -> 0 | ... N11: =SUM(N5:N10) -> 0
A13: Rủi ro / cơ hội 1
A14: Rủi ro / cơ hội 2
A15: Rủi ro / cơ hội 3
A16: Quyết định cần chốt

Sheet 09_TuKiemTra
A1: 09 · Tự kiểm tra trước khi nộp
A2: Đánh dấu ✔ khi đạt.
A4: Tiêu chí | B4: Đạt?
A5: Dữ liệu: mọi điều chỉnh có trong nhật ký, không sửa đè số gốc
A6: Mỗi chuỗi có ≥ 3 phương pháp, có mốc Naive/Seasonal Naive, chấm trên 6 tháng test
A7: Không tối ưu tham số trên dữ liệu test; không dùng biến tương lai chưa biết
A8: Tết 2027 đã được xem xét cho mã nhạy Tết; KM đã duyệt đã được đưa vào có giả định
A9: Mọi điều chỉnh ≠ 0 có mã giả định và nguồn
A10: σ là sai số ngoài mẫu (không phải độ lệch chuẩn nhu cầu); SS và ROP có đơn vị đúng
A11: File bàn giao đủ 72 dòng (6 chuỗi × 12 tháng), số chưa giới hạn năng lực
A12: Tóm tắt S&OP: có giá trị tiền, 3 rủi ro/cơ hội, quyết định cần chốt
A13: Báo cáo 6–8 trang theo cấu trúc kim tự tháp ngược; slide ≤ 8 phút
